2022-07-21 15:50:01,600 INFO  ==============================================================
2022-07-21 15:50:01,601 INFO  Id:    SoftwareManagement.sm_apt_install_remove_multiple_mixed
2022-07-21 15:50:01,603 INFO  Dir:   software_management_end_to_end/
2022-07-21 15:50:01,603 INFO  Title: Validate end to end behaviour for the apt plugin for multiple packages with mixed versions
2022-07-21 15:50:01,604 INFO  ==============================================================
2022-07-21 15:50:01,625 INFO  Using sw id database: {'asciijump': '5475369', 'robotfindskitten': '5474869', 'squirrel3': '5475279', 'rolldice': '5152439', 'moon-buggy': '5439204', 'apple': '5495053', 'banana': '5494888', 'cherry': '5495382', 'watermelon': '5494510', 'registry': '8018911', 'hello-world': '8021526', 'docker/getting-started': '8021973', 'alpine': '7991792'}
2022-07-21 15:50:01,626 INFO  EnvironmentC8y Setup
2022-07-21 15:50:02,240 INFO  Executed systemctl<serv_mapper1>, exit status 3
2022-07-21 15:50:02,376 INFO  Restarting mosquitto too frequently in the last 10 seconds. It was only up for 4 seconds
2022-07-21 15:50:02,378 INFO  Delaying execution by 7 seconds
2022-07-21 15:50:23,310 INFO  Executed sudo<tedge_connect_c8y>, exit status 0, duration 13 secs
2022-07-21 15:50:23,976 INFO  Executed sudo<tedge_connect_c8y_test>, exit status 0
2022-07-21 15:50:24,490 INFO  Executed systemctl<serv_mosq2>, exit status 0
2022-07-21 15:50:24,953 INFO  Executed systemctl<serv_mapper3>, exit status 0
2022-07-21 15:50:27,175 INFO  State of current operation: SUCCESSFUL
2022-07-21 15:50:27,404 INFO  Assert that (False == value) with value=False ... passed
2022-07-21 15:50:27,648 INFO  Assert that (False == value) with value=False ... passed
2022-07-21 15:50:27,873 INFO  Assert that (False == value) with value=False ... passed
2022-07-21 15:50:28,101 INFO  Assert that (False == value) with value=False ... passed
2022-07-21 15:50:28,318 INFO  Package moon-buggy is installed
2022-07-21 15:50:28,351 WARN  Assert that (False == value) with value=True ... failed 
2022-07-21 15:50:29,604 INFO  Response status: 201
2022-07-21 15:50:29,606 INFO  Response to action: {
    "creationTime": "2022-07-21T15:50:29.549Z",
    "deviceId": "21116856",
    "deviceName": "m32sd10b",
    "self": "https://t493319102.eu-latest.cumulocity.com/devicecontrol/operations/21145008",
    "id": "21145008",
    "status": "PENDING",
    "description": "Apply software changes, triggered from PySys: [{'action': 'install', 'id': '5475369', 'name': 'asciijump', 'url': ' ', 'version': '::apt'}, {'action': 'install', 'id': '5474869', 'name': 'robotfindskitten', 'url': ' ', 'version': ' '}, {'action': 'install', 'id': '5475279', 'name': 'squirrel3', 'url': ' ', 'version': '3.1-7::apt'}, {'action': 'install', 'id': '5152439', 'name': 'rolldice', 'url': ' ', 'version': '1.16-1+b1'}, {'action': 'install', 'id': '5439204', 'name': 'moon-buggy', 'url': ' ', 'version': '1:1.0.51-12'}, {'action': 'install', 'id': '5475369', 'name': 'asciijump', 'url': ' ', 'version': '::apt'}]",
    "c8y_SoftwareUpdate": [
        {
            "name": "asciijump",
            "action": "install",
            "id": "5475369",
            "version": "::apt",
            "url": " "
        },
        {
            "name": "robotfindskitten",
            "action": "install",
            "id": "5474869",
            "version": " ",
            "url": " "
        },
        {
            "name": "squirrel3",
            "action": "install",
            "id": "5475279",
            "version": "3.1-7::apt",
            "url": " "
        },
        {
            "name": "rolldice",
            "action": "install",
            "id": "5152439",
            "version": "1.16-1+b1",
            "url": " "
        },
        {
            "name": "moon-buggy",
            "action": "install",
            "id": "5439204",
            "version": "1:1.0.51-12",
            "url": " "
        },
        {
            "name": "asciijump",
            "action": "install",
            "id": "5475369",
            "version": "::apt",
            "url": " "
        }
    ]
}
2022-07-21 15:50:29,607 INFO  Started operation: {'creationTime': '2022-07-21T15:50:29.549Z', 'deviceId': '21116856', 'deviceName': 'm32sd10b', 'self': 'https://t493319102.eu-latest.cumulocity.com/devicecontrol/operations/21145008', 'id': '21145008', 'status': 'PENDING', 'description': "Apply software changes, triggered from PySys: [{'action': 'install', 'id': '5475369', 'name': 'asciijump', 'url': ' ', 'version': '::apt'}, {'action': 'install', 'id': '5474869', 'name': 'robotfindskitten', 'url': ' ', 'version': ' '}, {'action': 'install', 'id': '5475279', 'name': 'squirrel3', 'url': ' ', 'version': '3.1-7::apt'}, {'action': 'install', 'id': '5152439', 'name': 'rolldice', 'url': ' ', 'version': '1.16-1+b1'}, {'action': 'install', 'id': '5439204', 'name': 'moon-buggy', 'url': ' ', 'version': '1:1.0.51-12'}, {'action': 'install', 'id': '5475369', 'name': 'asciijump', 'url': ' ', 'version': '::apt'}]", 'c8y_SoftwareUpdate': [{'name': 'asciijump', 'action': 'install', 'id': '5475369', 'version': '::apt', 'url': ' '}, {'name': 'robotfindskitten', 'action': 'install', 'id': '5474869', 'version': ' ', 'url': ' '}, {'name': 'squirrel3', 'action': 'install', 'id': '5475279', 'version': '3.1-7::apt', 'url': ' '}, {'name': 'rolldice', 'action': 'install', 'id': '5152439', 'version': '1.16-1+b1', 'url': ' '}, {'name': 'moon-buggy', 'action': 'install', 'id': '5439204', 'version': '1:1.0.51-12', 'url': ' '}, {'name': 'asciijump', 'action': 'install', 'id': '5475369', 'version': '::apt', 'url': ' '}]}
2022-07-21 15:50:31,829 INFO  State of operation 21145008 : PENDING
2022-07-21 15:50:34,062 INFO  State of operation 21145008 : EXECUTING
2022-07-21 15:50:36,295 INFO  State of operation 21145008 : EXECUTING
2022-07-21 15:50:38,524 INFO  State of operation 21145008 : EXECUTING
2022-07-21 15:50:40,740 INFO  State of operation 21145008 : EXECUTING
2022-07-21 15:50:42,984 INFO  State of operation 21145008 : EXECUTING
2022-07-21 15:50:45,723 INFO  State of operation 21145008 : EXECUTING
2022-07-21 15:50:48,834 WARN  ConnectionError occurred while running test - ('Connection aborted.', ConnectionResetError(104, 'Connection reset by peer'))
Traceback (most recent call last):
  File "/home/pi/env-pysys/lib/python3.7/site-packages/urllib3/connectionpool.py", line 710, in urlopen
    chunked=chunked,
  File "/home/pi/env-pysys/lib/python3.7/site-packages/urllib3/connectionpool.py", line 386, in _make_request
    self._validate_conn(conn)
  File "/home/pi/env-pysys/lib/python3.7/site-packages/urllib3/connectionpool.py", line 1040, in _validate_conn
    conn.connect()
  File "/home/pi/env-pysys/lib/python3.7/site-packages/urllib3/connection.py", line 424, in connect
    tls_in_tls=tls_in_tls,
  File "/home/pi/env-pysys/lib/python3.7/site-packages/urllib3/util/ssl_.py", line 450, in ssl_wrap_socket
    sock, context, tls_in_tls, server_hostname=server_hostname
  File "/home/pi/env-pysys/lib/python3.7/site-packages/urllib3/util/ssl_.py", line 493, in _ssl_wrap_socket_impl
    return ssl_context.wrap_socket(sock, server_hostname=server_hostname)
  File "/usr/lib/python3.7/ssl.py", line 412, in wrap_socket
    session=session
  File "/usr/lib/python3.7/ssl.py", line 853, in _create
    self.do_handshake()
  File "/usr/lib/python3.7/ssl.py", line 1117, in do_handshake
    self._sslobj.do_handshake()
ConnectionResetError: [Errno 104] Connection reset by peer

During handling of the above exception, another exception occurred:

Traceback (most recent call last):
  File "/home/pi/env-pysys/lib/python3.7/site-packages/requests/adapters.py", line 449, in send
    timeout=timeout
  File "/home/pi/env-pysys/lib/python3.7/site-packages/urllib3/connectionpool.py", line 786, in urlopen
    method, url, error=e, _pool=self, _stacktrace=sys.exc_info()[2]
  File "/home/pi/env-pysys/lib/python3.7/site-packages/urllib3/util/retry.py", line 550, in increment
    raise six.reraise(type(error), error, _stacktrace)
  File "/home/pi/env-pysys/lib/python3.7/site-packages/urllib3/packages/six.py", line 769, in reraise
    raise value.with_traceback(tb)
  File "/home/pi/env-pysys/lib/python3.7/site-packages/urllib3/connectionpool.py", line 710, in urlopen
    chunked=chunked,
  File "/home/pi/env-pysys/lib/python3.7/site-packages/urllib3/connectionpool.py", line 386, in _make_request
    self._validate_conn(conn)
  File "/home/pi/env-pysys/lib/python3.7/site-packages/urllib3/connectionpool.py", line 1040, in _validate_conn
    conn.connect()
  File "/home/pi/env-pysys/lib/python3.7/site-packages/urllib3/connection.py", line 424, in connect
    tls_in_tls=tls_in_tls,
  File "/home/pi/env-pysys/lib/python3.7/site-packages/urllib3/util/ssl_.py", line 450, in ssl_wrap_socket
    sock, context, tls_in_tls, server_hostname=server_hostname
  File "/home/pi/env-pysys/lib/python3.7/site-packages/urllib3/util/ssl_.py", line 493, in _ssl_wrap_socket_impl
    return ssl_context.wrap_socket(sock, server_hostname=server_hostname)
  File "/usr/lib/python3.7/ssl.py", line 412, in wrap_socket
    session=session
  File "/usr/lib/python3.7/ssl.py", line 853, in _create
    self.do_handshake()
  File "/usr/lib/python3.7/ssl.py", line 1117, in do_handshake
    self._sslobj.do_handshake()
urllib3.exceptions.ProtocolError: ('Connection aborted.', ConnectionResetError(104, 'Connection reset by peer'))

During handling of the above exception, another exception occurred:

Traceback (most recent call last):
  File "/home/pi/env-pysys/lib/python3.7/site-packages/pysys/baserunner.py", line 1294, in __call__
    self.testObj.execute()
  File "/home/pi/actions-runner/_work/thin-edge.io/thin-edge.io/tests/PySys/software_management_end_to_end/sm_apt_install_remove_multiple_mixed/run.py", line 89, in execute
    self.wait_until_succcess()
  File "/home/pi/actions-runner/_work/thin-edge.io/thin-edge.io/tests/PySys/software_management_end_to_end/environment_sm_management.py", line 324, in wait_until_succcess
    self.wait_until_status("SUCCESSFUL")
  File "/home/pi/actions-runner/_work/thin-edge.io/thin-edge.io/tests/PySys/software_management_end_to_end/environment_sm_management.py", line 354, in wait_until_status
    current_status = self.get_status_of_operation()
  File "/home/pi/actions-runner/_work/thin-edge.io/thin-edge.io/tests/PySys/software_management_end_to_end/environment_sm_management.py", line 300, in get_status_of_operation
    req = requests.get(url, headers=self.header, timeout=self.timeout_req)
  File "/home/pi/env-pysys/lib/python3.7/site-packages/requests/api.py", line 76, in get
    return request('get', url, params=params, **kwargs)
  File "/home/pi/env-pysys/lib/python3.7/site-packages/requests/api.py", line 61, in request
    return session.request(method=method, url=url, **kwargs)
  File "/home/pi/env-pysys/lib/python3.7/site-packages/requests/sessions.py", line 542, in request
    resp = self.send(prep, **send_kwargs)
  File "/home/pi/env-pysys/lib/python3.7/site-packages/requests/sessions.py", line 655, in send
    r = adapter.send(request, **kwargs)
  File "/home/pi/env-pysys/lib/python3.7/site-packages/requests/adapters.py", line 498, in send
    raise ConnectionError(err, request=request)
requests.exceptions.ConnectionError: ('Connection aborted.', ConnectionResetError(104, 'Connection reset by peer'))
2022-07-21 15:50:49,894 WARN  ConnectionError: ('Connection aborted.', ConnectionResetError(104, 'Connection reset by peer')) ... blocked 
2022-07-21 15:50:49,896 INFO  
2022-07-21 15:50:49,896 INFO  cleanup:
2022-07-21 15:50:56,232 INFO  Executed sudo<tedge_disconnect_c8y>, exit status 0
2022-07-21 15:50:56,795 INFO  Executed systemctl<serv_mapper5>, exit status 3
2022-07-21 15:50:56,799 INFO  
2022-07-21 15:50:56,800 INFO  Test duration: 55.21 secs
2022-07-21 15:50:56,801 INFO  Test final outcome:  BLOCKED
2022-07-21 15:50:56,802 INFO  Test outcome reason: ConnectionError: ('Connection aborted.', ConnectionResetError(104, 'Connection reset by peer')) (+1 other failures)
2022-07-21 15:50:56,803 INFO  
