2022-05-23 19:05:02,831 INFO  ==============================================================
2022-05-23 19:05:02,832 INFO  Id:    log_request_num_lines
2022-05-23 19:05:02,833 INFO  Dir:   log_request_end_to_end/
2022-05-23 19:05:02,834 INFO  Title: Validate end to end behaviour for the log request operation check for number of lines
2022-05-23 19:05:02,835 INFO  ==============================================================
2022-05-23 19:05:02,846 INFO  EnvironmentC8y Setup
2022-05-23 19:05:03,408 INFO  Executed systemctl<serv_mapper1>, exit status 3
2022-05-23 19:05:03,512 INFO  Restarting mosquitto too frequently in the last 10 seconds. It was only up for 4 seconds
2022-05-23 19:05:03,514 INFO  Delaying execution by 7 seconds
2022-05-23 19:05:25,266 INFO  Executed sudo<tedge_connect_c8y>, exit status 0, duration 14 secs
2022-05-23 19:05:25,835 INFO  Executed sudo<tedge_connect_c8y_test>, exit status 0
2022-05-23 19:05:26,303 INFO  Executed systemctl<serv_mosq2>, exit status 0
2022-05-23 19:05:26,766 INFO  Executed systemctl<serv_mapper3>, exit status 0
2022-05-23 19:05:27,280 INFO  Executed sudo<rm_logs>, exit status 0
2022-05-23 19:05:27,861 INFO  Executed sudo<move_logs>, exit status 0
2022-05-23 19:05:28,315 INFO  log response None
2022-05-23 19:05:28,317 WARN  retry, retrying in 1 seconds...
2022-05-23 19:05:29,526 INFO  log response None
2022-05-23 19:05:29,527 WARN  retry, retrying in 1 seconds...
2022-05-23 19:05:30,737 INFO  log response None
2022-05-23 19:05:30,738 WARN  retry, retrying in 1 seconds...
2022-05-23 19:05:31,965 INFO  log response None
2022-05-23 19:05:31,967 WARN  retry, retrying in 1 seconds...
2022-05-23 19:05:33,179 INFO  log response None
2022-05-23 19:05:33,180 WARN  retry, retrying in 1 seconds...
2022-05-23 19:05:34,388 INFO  log response None
2022-05-23 19:05:34,389 WARN  retry, retrying in 1 seconds...
2022-05-23 19:05:35,598 INFO  log response None
2022-05-23 19:05:35,599 WARN  retry, retrying in 1 seconds...
2022-05-23 19:05:36,809 INFO  log response None
2022-05-23 19:05:36,810 WARN  retry, retrying in 1 seconds...
2022-05-23 19:05:38,017 INFO  log response None
2022-05-23 19:05:38,018 WARN  retry, retrying in 1 seconds...
2022-05-23 19:05:39,227 INFO  log response None
2022-05-23 19:05:39,228 WARN  retry, retrying in 1 seconds...
2022-05-23 19:05:40,439 INFO  log response None
2022-05-23 19:05:40,440 WARN  retry, retrying in 1 seconds...
2022-05-23 19:05:41,699 INFO  log response None
2022-05-23 19:05:41,701 WARN  retry, retrying in 1 seconds...
2022-05-23 19:05:42,909 INFO  log response None
2022-05-23 19:05:42,910 WARN  retry, retrying in 1 seconds...
2022-05-23 19:05:44,116 INFO  log response None
2022-05-23 19:05:44,118 WARN  retry, retrying in 1 seconds...
2022-05-23 19:05:45,372 INFO  log response None
2022-05-23 19:05:45,373 WARN  retry, retrying in 1 seconds...
2022-05-23 19:05:46,626 INFO  log response None
2022-05-23 19:05:46,627 WARN  retry, retrying in 1 seconds...
2022-05-23 19:05:47,837 INFO  log response None
2022-05-23 19:05:47,838 WARN  retry, retrying in 1 seconds...
2022-05-23 19:05:49,041 INFO  log response None
2022-05-23 19:05:49,044 WARN  retry, retrying in 1 seconds...
2022-05-23 19:05:50,246 INFO  log response None
2022-05-23 19:05:50,247 WARN  retry, retrying in 1 seconds...
2022-05-23 19:05:51,504 INFO  log response None
2022-05-23 19:05:51,507 WARN  Exception occurred while running test - retry
Traceback (most recent call last):
  File "/home/pi/env-pysys/lib/python3.7/site-packages/pysys/baserunner.py", line 1296, in __call__
    self.testObj.validate()
  File "/home/pi/actions-runner/_work/thin-edge.io/thin-edge.io/tests/PySys/log_request_end_to_end/log_request_num_lines/run.py", line 44, in validate
    self.assertThat("True == value", value=self.wait_until_logs_retrieved())
  File "/home/pi/env-pysys/lib/python3.7/site-packages/decorator.py", line 232, in fun
    return caller(func, *(extras + args), **kw)
  File "/home/pi/env-pysys/lib/python3.7/site-packages/retry/api.py", line 74, in retry_decorator
    logger)
  File "/home/pi/env-pysys/lib/python3.7/site-packages/retry/api.py", line 33, in __retry_internal
    return f()
  File "/home/pi/actions-runner/_work/thin-edge.io/thin-edge.io/tests/PySys/log_request_end_to_end/log_request_num_lines/run.py", line 52, in wait_until_logs_retrieved
    raise Exception("retry")
Exception: retry
2022-05-23 19:05:51,529 WARN  Exception: retry ... blocked 
2022-05-23 19:05:51,531 INFO  
2022-05-23 19:05:51,532 INFO  cleanup:
2022-05-23 19:05:52,112 INFO  Executed sudo<rm_logs>, exit status 0
2022-05-23 19:05:52,624 INFO  Executed sudo<rm_tmp_logs>, exit status 0
2022-05-23 19:05:53,204 INFO  Executed sudo<send_failed>, exit status 0
2022-05-23 19:05:57,146 INFO  Executed sudo<tedge_disconnect_c8y>, exit status 0
2022-05-23 19:05:57,714 INFO  Executed systemctl<serv_mapper5>, exit status 3
2022-05-23 19:05:57,718 INFO  
2022-05-23 19:05:57,719 INFO  Test duration: 54.89 secs
2022-05-23 19:05:57,720 INFO  Test final outcome:  BLOCKED
2022-05-23 19:05:57,721 INFO  Test outcome reason: Exception: retry
2022-05-23 19:05:57,722 INFO  
