2022-07-26 17:29:30,829 INFO  ==============================================================
2022-07-26 17:29:30,830 INFO  Id:    SoftwareManagement.sm_apt_install_remove_with_version
2022-07-26 17:29:30,832 INFO  Dir:   software_management_end_to_end/
2022-07-26 17:29:30,833 INFO  Title: Validate end to end behaviour for the apt plugin for packages with version
2022-07-26 17:29:30,834 INFO  ==============================================================
2022-07-26 17:29:30,842 INFO  Using sw id database: {'asciijump': '5475369', 'robotfindskitten': '5474869', 'squirrel3': '5475279', 'rolldice': '5152439', 'moon-buggy': '5439204', 'apple': '5495053', 'banana': '5494888', 'cherry': '5495382', 'watermelon': '5494510', 'registry': '8018911', 'hello-world': '8021526', 'docker/getting-started': '8021973', 'alpine': '7991792'}
2022-07-26 17:29:30,843 INFO  EnvironmentC8y Setup
2022-07-26 17:29:31,412 INFO  Executed systemctl<serv_mapper1>, exit status 3
2022-07-26 17:29:31,525 INFO  Restarting mosquitto too frequently in the last 10 seconds. It was only up for 5 seconds
2022-07-26 17:29:31,526 INFO  Delaying execution by 6 seconds
2022-07-26 17:29:51,563 INFO  Executed sudo<tedge_connect_c8y>, exit status 0, duration 14 secs
2022-07-26 17:29:52,178 INFO  Executed sudo<tedge_connect_c8y_test>, exit status 0
2022-07-26 17:29:52,641 INFO  Executed systemctl<serv_mosq2>, exit status 0
2022-07-26 17:29:53,104 INFO  Executed systemctl<serv_mapper3>, exit status 0
2022-07-26 17:29:55,333 INFO  State of current operation: FAILED
2022-07-26 17:29:55,611 INFO  Assert that (False == value) with value=False ... passed
2022-07-26 17:29:56,256 INFO  Response status: 201
2022-07-26 17:29:56,257 INFO  Response to action: {
    "delivery": {
        "log": [],
        "time": "2022-07-26T17:29:56.230Z",
        "status": "PENDING"
    },
    "creationTime": "2022-07-26T17:29:56.190Z",
    "deviceId": "21435313",
    "deviceName": "m32sd10d",
    "self": "https://t493319102.eu-latest.cumulocity.com/devicecontrol/operations/21453331",
    "id": "21453331",
    "status": "PENDING",
    "description": "Apply software changes, triggered from PySys: [{'name': 'rolldice', 'id': '5152439', 'version': '1.16-1+b1', 'url': '', 'action': 'install'}]",
    "c8y_SoftwareUpdate": [
        {
            "name": "rolldice",
            "action": "install",
            "id": "5152439",
            "version": "1.16-1+b1",
            "url": ""
        }
    ]
}
2022-07-26 17:29:56,258 INFO  Started operation: {'delivery': {'log': [], 'time': '2022-07-26T17:29:56.230Z', 'status': 'PENDING'}, 'creationTime': '2022-07-26T17:29:56.190Z', 'deviceId': '21435313', 'deviceName': 'm32sd10d', 'self': 'https://t493319102.eu-latest.cumulocity.com/devicecontrol/operations/21453331', 'id': '21453331', 'status': 'PENDING', 'description': "Apply software changes, triggered from PySys: [{'name': 'rolldice', 'id': '5152439', 'version': '1.16-1+b1', 'url': '', 'action': 'install'}]", 'c8y_SoftwareUpdate': [{'name': 'rolldice', 'action': 'install', 'id': '5152439', 'version': '1.16-1+b1', 'url': ''}]}
2022-07-26 17:29:58,466 INFO  State of operation 21453331 : PENDING
2022-07-26 17:30:00,696 INFO  State of operation 21453331 : EXECUTING
2022-07-26 17:30:02,912 INFO  State of operation 21453331 : EXECUTING
2022-07-26 17:30:05,122 INFO  State of operation 21453331 : EXECUTING
2022-07-26 17:30:07,348 INFO  State of operation 21453331 : EXECUTING
2022-07-26 17:30:09,569 INFO  State of operation 21453331 : EXECUTING
2022-07-26 17:30:13,177 INFO  State of operation 21453331 : EXECUTING
2022-07-26 17:30:15,933 INFO  State of operation 21453331 : EXECUTING
2022-07-26 17:30:18,503 INFO  State of operation 21453331 : EXECUTING
2022-07-26 17:30:20,730 INFO  State of operation 21453331 : EXECUTING
2022-07-26 17:30:22,945 INFO  State of operation 21453331 : EXECUTING
2022-07-26 17:30:25,177 INFO  State of operation 21453331 : EXECUTING
2022-07-26 17:30:27,399 INFO  State of operation 21453331 : EXECUTING
2022-07-26 17:30:29,628 INFO  State of operation 21453331 : EXECUTING
2022-07-26 17:30:31,858 INFO  State of operation 21453331 : SUCCESSFUL
2022-07-26 17:30:32,078 INFO  Package rolldice is installed
2022-07-26 17:30:32,080 INFO  Assert that (True == value) with value=True ... passed
2022-07-26 17:30:32,530 INFO  Response status: 201
2022-07-26 17:30:32,532 INFO  Response to action: {
    "delivery": {
        "log": [],
        "time": "2022-07-26T17:30:32.505Z",
        "status": "PENDING"
    },
    "creationTime": "2022-07-26T17:30:32.407Z",
    "deviceId": "21435313",
    "deviceName": "m32sd10d",
    "self": "https://t493319102.eu-latest.cumulocity.com/devicecontrol/operations/21453343",
    "id": "21453343",
    "status": "PENDING",
    "description": "Apply software changes, triggered from PySys: [{'name': 'rolldice', 'id': '5152439', 'version': '88::apt', 'url': '', 'action': 'delete'}]",
    "c8y_SoftwareUpdate": [
        {
            "name": "rolldice",
            "action": "delete",
            "id": "5152439",
            "version": "88::apt",
            "url": ""
        }
    ]
}
2022-07-26 17:30:32,533 INFO  Started operation: {'delivery': {'log': [], 'time': '2022-07-26T17:30:32.505Z', 'status': 'PENDING'}, 'creationTime': '2022-07-26T17:30:32.407Z', 'deviceId': '21435313', 'deviceName': 'm32sd10d', 'self': 'https://t493319102.eu-latest.cumulocity.com/devicecontrol/operations/21453343', 'id': '21453343', 'status': 'PENDING', 'description': "Apply software changes, triggered from PySys: [{'name': 'rolldice', 'id': '5152439', 'version': '88::apt', 'url': '', 'action': 'delete'}]", 'c8y_SoftwareUpdate': [{'name': 'rolldice', 'action': 'delete', 'id': '5152439', 'version': '88::apt', 'url': ''}]}
2022-07-26 17:30:34,748 INFO  State of operation 21453343 : PENDING
2022-07-26 17:30:36,997 INFO  State of operation 21453343 : EXECUTING
2022-07-26 17:30:39,224 INFO  State of operation 21453343 : EXECUTING
2022-07-26 17:30:41,438 INFO  State of operation 21453343 : EXECUTING
2022-07-26 17:30:43,647 INFO  State of operation 21453343 : EXECUTING
2022-07-26 17:30:46,267 WARN  ConnectionError occurred while running test - ('Connection aborted.', ConnectionResetError(104, 'Connection reset by peer'))
Traceback (most recent call last):
  File "/home/pi/env-pysys/lib/python3.7/site-packages/urllib3/connectionpool.py", line 710, in urlopen
    chunked=chunked,
  File "/home/pi/env-pysys/lib/python3.7/site-packages/urllib3/connectionpool.py", line 386, in _make_request
    self._validate_conn(conn)
  File "/home/pi/env-pysys/lib/python3.7/site-packages/urllib3/connectionpool.py", line 1040, in _validate_conn
    conn.connect()
  File "/home/pi/env-pysys/lib/python3.7/site-packages/urllib3/connection.py", line 424, in connect
    tls_in_tls=tls_in_tls,
  File "/home/pi/env-pysys/lib/python3.7/site-packages/urllib3/util/ssl_.py", line 450, in ssl_wrap_socket
    sock, context, tls_in_tls, server_hostname=server_hostname
  File "/home/pi/env-pysys/lib/python3.7/site-packages/urllib3/util/ssl_.py", line 493, in _ssl_wrap_socket_impl
    return ssl_context.wrap_socket(sock, server_hostname=server_hostname)
  File "/usr/lib/python3.7/ssl.py", line 412, in wrap_socket
    session=session
  File "/usr/lib/python3.7/ssl.py", line 853, in _create
    self.do_handshake()
  File "/usr/lib/python3.7/ssl.py", line 1117, in do_handshake
    self._sslobj.do_handshake()
ConnectionResetError: [Errno 104] Connection reset by peer

During handling of the above exception, another exception occurred:

Traceback (most recent call last):
  File "/home/pi/env-pysys/lib/python3.7/site-packages/requests/adapters.py", line 449, in send
    timeout=timeout
  File "/home/pi/env-pysys/lib/python3.7/site-packages/urllib3/connectionpool.py", line 786, in urlopen
    method, url, error=e, _pool=self, _stacktrace=sys.exc_info()[2]
  File "/home/pi/env-pysys/lib/python3.7/site-packages/urllib3/util/retry.py", line 550, in increment
    raise six.reraise(type(error), error, _stacktrace)
  File "/home/pi/env-pysys/lib/python3.7/site-packages/urllib3/packages/six.py", line 769, in reraise
    raise value.with_traceback(tb)
  File "/home/pi/env-pysys/lib/python3.7/site-packages/urllib3/connectionpool.py", line 710, in urlopen
    chunked=chunked,
  File "/home/pi/env-pysys/lib/python3.7/site-packages/urllib3/connectionpool.py", line 386, in _make_request
    self._validate_conn(conn)
  File "/home/pi/env-pysys/lib/python3.7/site-packages/urllib3/connectionpool.py", line 1040, in _validate_conn
    conn.connect()
  File "/home/pi/env-pysys/lib/python3.7/site-packages/urllib3/connection.py", line 424, in connect
    tls_in_tls=tls_in_tls,
  File "/home/pi/env-pysys/lib/python3.7/site-packages/urllib3/util/ssl_.py", line 450, in ssl_wrap_socket
    sock, context, tls_in_tls, server_hostname=server_hostname
  File "/home/pi/env-pysys/lib/python3.7/site-packages/urllib3/util/ssl_.py", line 493, in _ssl_wrap_socket_impl
    return ssl_context.wrap_socket(sock, server_hostname=server_hostname)
  File "/usr/lib/python3.7/ssl.py", line 412, in wrap_socket
    session=session
  File "/usr/lib/python3.7/ssl.py", line 853, in _create
    self.do_handshake()
  File "/usr/lib/python3.7/ssl.py", line 1117, in do_handshake
    self._sslobj.do_handshake()
urllib3.exceptions.ProtocolError: ('Connection aborted.', ConnectionResetError(104, 'Connection reset by peer'))

During handling of the above exception, another exception occurred:

Traceback (most recent call last):
  File "/home/pi/env-pysys/lib/python3.7/site-packages/pysys/baserunner.py", line 1294, in __call__
    self.testObj.execute()
  File "/home/pi/actions-runner/_work/thin-edge.io/thin-edge.io/tests/PySys/software_management_end_to_end/sm_apt_install_remove_with_version/run.py", line 50, in execute
    self.wait_until_fail()
  File "/home/pi/actions-runner/_work/thin-edge.io/thin-edge.io/tests/PySys/software_management_end_to_end/environment_sm_management.py", line 328, in wait_until_fail
    self.wait_until_status("FAILED")
  File "/home/pi/actions-runner/_work/thin-edge.io/thin-edge.io/tests/PySys/software_management_end_to_end/environment_sm_management.py", line 354, in wait_until_status
    current_status = self.get_status_of_operation()
  File "/home/pi/actions-runner/_work/thin-edge.io/thin-edge.io/tests/PySys/software_management_end_to_end/environment_sm_management.py", line 300, in get_status_of_operation
    req = requests.get(url, headers=self.header, timeout=self.timeout_req)
  File "/home/pi/env-pysys/lib/python3.7/site-packages/requests/api.py", line 76, in get
    return request('get', url, params=params, **kwargs)
  File "/home/pi/env-pysys/lib/python3.7/site-packages/requests/api.py", line 61, in request
    return session.request(method=method, url=url, **kwargs)
  File "/home/pi/env-pysys/lib/python3.7/site-packages/requests/sessions.py", line 542, in request
    resp = self.send(prep, **send_kwargs)
  File "/home/pi/env-pysys/lib/python3.7/site-packages/requests/sessions.py", line 655, in send
    r = adapter.send(request, **kwargs)
  File "/home/pi/env-pysys/lib/python3.7/site-packages/requests/adapters.py", line 498, in send
    raise ConnectionError(err, request=request)
requests.exceptions.ConnectionError: ('Connection aborted.', ConnectionResetError(104, 'Connection reset by peer'))
2022-07-26 17:30:49,661 WARN  ConnectionError: ('Connection aborted.', ConnectionResetError(104, 'Connection reset by peer')) ... blocked 
2022-07-26 17:30:49,663 INFO  
2022-07-26 17:30:49,664 INFO  cleanup:
2022-07-26 17:30:56,226 INFO  Executed sudo<tedge_disconnect_c8y>, exit status 0
2022-07-26 17:30:56,789 INFO  Executed systemctl<serv_mapper5>, exit status 3
2022-07-26 17:30:56,793 INFO  
2022-07-26 17:30:56,794 INFO  Test duration: 85.98 secs
2022-07-26 17:30:56,795 INFO  Test final outcome:  BLOCKED
2022-07-26 17:30:56,796 INFO  Test outcome reason: ConnectionError: ('Connection aborted.', ConnectionResetError(104, 'Connection reset by peer'))
2022-07-26 17:30:56,797 INFO  
