2022-07-25 09:33:33,337 INFO  ==============================================================
2022-07-25 09:33:33,338 INFO  Id:    SoftwareManagement.sm_apt_install_remove
2022-07-25 09:33:33,339 INFO  Dir:   software_management_end_to_end/
2022-07-25 09:33:33,340 INFO  Title: Validate end to end behaviour for the apt plugin for installation and removal of packages
2022-07-25 09:33:33,340 INFO  ==============================================================
2022-07-25 09:33:33,346 INFO  Using sw id database: {'asciijump': '5475369', 'robotfindskitten': '5474869', 'squirrel3': '5475279', 'rolldice': '5152439', 'moon-buggy': '5439204', 'apple': '5495053', 'banana': '5494888', 'cherry': '5495382', 'watermelon': '5494510', 'registry': '8018911', 'hello-world': '8021526', 'docker/getting-started': '8021973', 'alpine': '7991792'}
2022-07-25 09:33:33,347 INFO  EnvironmentC8y Setup
2022-07-25 09:33:33,909 INFO  Executed systemctl<serv_mapper1>, exit status 3
2022-07-25 09:33:34,015 INFO  Restarting mosquitto too frequently in the last 10 seconds. It was only up for 4 seconds
2022-07-25 09:33:34,016 INFO  Delaying execution by 7 seconds
2022-07-25 09:33:54,922 INFO  Executed sudo<tedge_connect_c8y>, exit status 0, duration 13 secs
2022-07-25 09:33:55,546 INFO  Executed sudo<tedge_connect_c8y_test>, exit status 0
2022-07-25 09:33:56,010 INFO  Executed systemctl<serv_mosq2>, exit status 0
2022-07-25 09:33:56,494 INFO  Executed systemctl<serv_mapper3>, exit status 0
2022-07-25 09:33:58,711 INFO  State of current operation: FAILED
2022-07-25 09:33:59,146 INFO  Assert that (False == value) with value=False ... passed
2022-07-25 09:33:59,374 INFO  Response status: 201
2022-07-25 09:33:59,376 INFO  Response to action: {
    "creationTime": "2022-07-25T09:33:59.329Z",
    "deviceId": "21358818",
    "deviceName": "m32sd10d",
    "self": "https://t493319102.eu-latest.cumulocity.com/devicecontrol/operations/21368536",
    "id": "21368536",
    "status": "PENDING",
    "description": "Apply software changes, triggered from PySys: [{'name': 'rolldice', 'id': '5152439', 'version': '::apt', 'url': '', 'action': 'install'}]",
    "c8y_SoftwareUpdate": [
        {
            "name": "rolldice",
            "action": "install",
            "id": "5152439",
            "version": "::apt",
            "url": ""
        }
    ]
}
2022-07-25 09:33:59,377 INFO  Started operation: {'creationTime': '2022-07-25T09:33:59.329Z', 'deviceId': '21358818', 'deviceName': 'm32sd10d', 'self': 'https://t493319102.eu-latest.cumulocity.com/devicecontrol/operations/21368536', 'id': '21368536', 'status': 'PENDING', 'description': "Apply software changes, triggered from PySys: [{'name': 'rolldice', 'id': '5152439', 'version': '::apt', 'url': '', 'action': 'install'}]", 'c8y_SoftwareUpdate': [{'name': 'rolldice', 'action': 'install', 'id': '5152439', 'version': '::apt', 'url': ''}]}
2022-07-25 09:34:01,643 INFO  State of operation 21368536 : PENDING
2022-07-25 09:34:03,866 INFO  State of operation 21368536 : EXECUTING
2022-07-25 09:34:06,080 INFO  State of operation 21368536 : EXECUTING
2022-07-25 09:34:08,303 INFO  State of operation 21368536 : EXECUTING
2022-07-25 09:34:10,533 INFO  State of operation 21368536 : EXECUTING
2022-07-25 09:34:12,751 INFO  State of operation 21368536 : EXECUTING
2022-07-25 09:34:15,526 INFO  State of operation 21368536 : EXECUTING
2022-07-25 09:34:18,288 INFO  State of operation 21368536 : EXECUTING
2022-07-25 09:34:21,880 INFO  State of operation 21368536 : EXECUTING
2022-07-25 09:34:24,097 INFO  State of operation 21368536 : EXECUTING
2022-07-25 09:34:26,316 INFO  State of operation 21368536 : EXECUTING
2022-07-25 09:34:28,548 INFO  State of operation 21368536 : EXECUTING
2022-07-25 09:34:30,765 INFO  State of operation 21368536 : EXECUTING
2022-07-25 09:34:32,998 INFO  State of operation 21368536 : EXECUTING
2022-07-25 09:34:35,231 INFO  State of operation 21368536 : EXECUTING
2022-07-25 09:34:37,692 INFO  State of operation 21368536 : EXECUTING
2022-07-25 09:34:41,656 INFO  State of operation 21368536 : EXECUTING
2022-07-25 09:34:43,883 INFO  State of operation 21368536 : EXECUTING
2022-07-25 09:34:46,109 INFO  State of operation 21368536 : EXECUTING
2022-07-25 09:34:48,326 INFO  State of operation 21368536 : EXECUTING
2022-07-25 09:34:51,026 INFO  State of operation 21368536 : EXECUTING
2022-07-25 09:34:53,393 INFO  State of operation 21368536 : EXECUTING
2022-07-25 09:34:56,172 INFO  State of operation 21368536 : EXECUTING
2022-07-25 09:34:58,416 INFO  State of operation 21368536 : EXECUTING
2022-07-25 09:35:00,632 INFO  State of operation 21368536 : EXECUTING
2022-07-25 09:35:02,878 INFO  State of operation 21368536 : EXECUTING
2022-07-25 09:35:05,094 INFO  State of operation 21368536 : EXECUTING
2022-07-25 09:35:07,376 INFO  State of operation 21368536 : EXECUTING
2022-07-25 09:35:09,610 INFO  State of operation 21368536 : EXECUTING
2022-07-25 09:35:12,006 INFO  State of operation 21368536 : EXECUTING
2022-07-25 09:35:14,222 INFO  State of operation 21368536 : EXECUTING
2022-07-25 09:35:16,472 INFO  State of operation 21368536 : EXECUTING
2022-07-25 09:35:18,686 INFO  State of operation 21368536 : EXECUTING
2022-07-25 09:35:20,893 INFO  State of operation 21368536 : SUCCESSFUL
2022-07-25 09:35:21,147 INFO  Package rolldice is installed
2022-07-25 09:35:21,149 INFO  Assert that (True == value) with value=True ... passed
2022-07-25 09:35:21,387 INFO  Response status: 201
2022-07-25 09:35:21,389 INFO  Response to action: {
    "creationTime": "2022-07-25T09:35:21.333Z",
    "deviceId": "21358818",
    "deviceName": "m32sd10d",
    "self": "https://t493319102.eu-latest.cumulocity.com/devicecontrol/operations/21368546",
    "id": "21368546",
    "status": "PENDING",
    "description": "Apply software changes, triggered from PySys: [{'name': 'rolldice', 'id': '5152439', 'version': '::apt', 'url': '', 'action': 'delete'}]",
    "c8y_SoftwareUpdate": [
        {
            "name": "rolldice",
            "action": "delete",
            "id": "5152439",
            "version": "::apt",
            "url": ""
        }
    ]
}
2022-07-25 09:35:21,389 INFO  Started operation: {'creationTime': '2022-07-25T09:35:21.333Z', 'deviceId': '21358818', 'deviceName': 'm32sd10d', 'self': 'https://t493319102.eu-latest.cumulocity.com/devicecontrol/operations/21368546', 'id': '21368546', 'status': 'PENDING', 'description': "Apply software changes, triggered from PySys: [{'name': 'rolldice', 'id': '5152439', 'version': '::apt', 'url': '', 'action': 'delete'}]", 'c8y_SoftwareUpdate': [{'name': 'rolldice', 'action': 'delete', 'id': '5152439', 'version': '::apt', 'url': ''}]}
2022-07-25 09:35:23,607 INFO  State of operation 21368546 : PENDING
2022-07-25 09:35:25,833 INFO  State of operation 21368546 : EXECUTING
2022-07-25 09:35:28,042 INFO  State of operation 21368546 : EXECUTING
2022-07-25 09:35:30,257 INFO  State of operation 21368546 : EXECUTING
2022-07-25 09:35:32,475 INFO  State of operation 21368546 : EXECUTING
2022-07-25 09:35:34,694 INFO  State of operation 21368546 : EXECUTING
2022-07-25 09:35:37,854 WARN  ConnectionError occurred while running test - ('Connection aborted.', ConnectionResetError(104, 'Connection reset by peer'))
Traceback (most recent call last):
  File "/home/pi/env-pysys/lib/python3.7/site-packages/urllib3/connectionpool.py", line 710, in urlopen
    chunked=chunked,
  File "/home/pi/env-pysys/lib/python3.7/site-packages/urllib3/connectionpool.py", line 386, in _make_request
    self._validate_conn(conn)
  File "/home/pi/env-pysys/lib/python3.7/site-packages/urllib3/connectionpool.py", line 1040, in _validate_conn
    conn.connect()
  File "/home/pi/env-pysys/lib/python3.7/site-packages/urllib3/connection.py", line 424, in connect
    tls_in_tls=tls_in_tls,
  File "/home/pi/env-pysys/lib/python3.7/site-packages/urllib3/util/ssl_.py", line 450, in ssl_wrap_socket
    sock, context, tls_in_tls, server_hostname=server_hostname
  File "/home/pi/env-pysys/lib/python3.7/site-packages/urllib3/util/ssl_.py", line 493, in _ssl_wrap_socket_impl
    return ssl_context.wrap_socket(sock, server_hostname=server_hostname)
  File "/usr/lib/python3.7/ssl.py", line 412, in wrap_socket
    session=session
  File "/usr/lib/python3.7/ssl.py", line 853, in _create
    self.do_handshake()
  File "/usr/lib/python3.7/ssl.py", line 1117, in do_handshake
    self._sslobj.do_handshake()
ConnectionResetError: [Errno 104] Connection reset by peer

During handling of the above exception, another exception occurred:

Traceback (most recent call last):
  File "/home/pi/env-pysys/lib/python3.7/site-packages/requests/adapters.py", line 449, in send
    timeout=timeout
  File "/home/pi/env-pysys/lib/python3.7/site-packages/urllib3/connectionpool.py", line 786, in urlopen
    method, url, error=e, _pool=self, _stacktrace=sys.exc_info()[2]
  File "/home/pi/env-pysys/lib/python3.7/site-packages/urllib3/util/retry.py", line 550, in increment
    raise six.reraise(type(error), error, _stacktrace)
  File "/home/pi/env-pysys/lib/python3.7/site-packages/urllib3/packages/six.py", line 769, in reraise
    raise value.with_traceback(tb)
  File "/home/pi/env-pysys/lib/python3.7/site-packages/urllib3/connectionpool.py", line 710, in urlopen
    chunked=chunked,
  File "/home/pi/env-pysys/lib/python3.7/site-packages/urllib3/connectionpool.py", line 386, in _make_request
    self._validate_conn(conn)
  File "/home/pi/env-pysys/lib/python3.7/site-packages/urllib3/connectionpool.py", line 1040, in _validate_conn
    conn.connect()
  File "/home/pi/env-pysys/lib/python3.7/site-packages/urllib3/connection.py", line 424, in connect
    tls_in_tls=tls_in_tls,
  File "/home/pi/env-pysys/lib/python3.7/site-packages/urllib3/util/ssl_.py", line 450, in ssl_wrap_socket
    sock, context, tls_in_tls, server_hostname=server_hostname
  File "/home/pi/env-pysys/lib/python3.7/site-packages/urllib3/util/ssl_.py", line 493, in _ssl_wrap_socket_impl
    return ssl_context.wrap_socket(sock, server_hostname=server_hostname)
  File "/usr/lib/python3.7/ssl.py", line 412, in wrap_socket
    session=session
  File "/usr/lib/python3.7/ssl.py", line 853, in _create
    self.do_handshake()
  File "/usr/lib/python3.7/ssl.py", line 1117, in do_handshake
    self._sslobj.do_handshake()
urllib3.exceptions.ProtocolError: ('Connection aborted.', ConnectionResetError(104, 'Connection reset by peer'))

During handling of the above exception, another exception occurred:

Traceback (most recent call last):
  File "/home/pi/env-pysys/lib/python3.7/site-packages/pysys/baserunner.py", line 1294, in __call__
    self.testObj.execute()
  File "/home/pi/actions-runner/_work/thin-edge.io/thin-edge.io/tests/PySys/software_management_end_to_end/sm_apt_install_remove/run.py", line 47, in execute
    self.wait_until_succcess()
  File "/home/pi/actions-runner/_work/thin-edge.io/thin-edge.io/tests/PySys/software_management_end_to_end/environment_sm_management.py", line 324, in wait_until_succcess
    self.wait_until_status("SUCCESSFUL")
  File "/home/pi/actions-runner/_work/thin-edge.io/thin-edge.io/tests/PySys/software_management_end_to_end/environment_sm_management.py", line 354, in wait_until_status
    current_status = self.get_status_of_operation()
  File "/home/pi/actions-runner/_work/thin-edge.io/thin-edge.io/tests/PySys/software_management_end_to_end/environment_sm_management.py", line 300, in get_status_of_operation
    req = requests.get(url, headers=self.header, timeout=self.timeout_req)
  File "/home/pi/env-pysys/lib/python3.7/site-packages/requests/api.py", line 76, in get
    return request('get', url, params=params, **kwargs)
  File "/home/pi/env-pysys/lib/python3.7/site-packages/requests/api.py", line 61, in request
    return session.request(method=method, url=url, **kwargs)
  File "/home/pi/env-pysys/lib/python3.7/site-packages/requests/sessions.py", line 542, in request
    resp = self.send(prep, **send_kwargs)
  File "/home/pi/env-pysys/lib/python3.7/site-packages/requests/sessions.py", line 655, in send
    r = adapter.send(request, **kwargs)
  File "/home/pi/env-pysys/lib/python3.7/site-packages/requests/adapters.py", line 498, in send
    raise ConnectionError(err, request=request)
requests.exceptions.ConnectionError: ('Connection aborted.', ConnectionResetError(104, 'Connection reset by peer'))
2022-07-25 09:35:38,775 WARN  ConnectionError: ('Connection aborted.', ConnectionResetError(104, 'Connection reset by peer')) ... blocked 
2022-07-25 09:35:38,776 INFO  
2022-07-25 09:35:38,777 INFO  cleanup:
2022-07-25 09:35:47,911 INFO  Executed sudo<tedge_disconnect_c8y>, exit status 0
2022-07-25 09:35:48,476 INFO  Executed systemctl<serv_mapper5>, exit status 3
2022-07-25 09:35:48,480 INFO  
2022-07-25 09:35:48,481 INFO  Test duration: 135.16 secs
2022-07-25 09:35:48,482 INFO  Test final outcome:  BLOCKED
2022-07-25 09:35:48,483 INFO  Test outcome reason: ConnectionError: ('Connection aborted.', ConnectionResetError(104, 'Connection reset by peer'))
2022-07-25 09:35:48,484 INFO  
