<?xml version="1.0" encoding="utf-8"?>
<testsuite failures="1" name="tedge_mapper_c8y_alarms" skipped="0" tests="1" time="26.25" timestamp="2022-07-01T07:06:06">
	<testcase classname="TedgeMapperC8yAlarm" name="tedge_mapper_c8y_alarms">
		<failure message="BLOCKED: ConnectionError: ('Connection aborted.', ConnectionResetError(104, 'Connection reset by peer'))" type="BLOCKED"/>
		<system-out>07:05:40 INFO  ==============================================================
07:05:40 INFO  Id:    tedge_mapper_c8y_alarms
07:05:40 INFO  Dir:   tedge_mapper_c8y/
07:05:40 INFO  Title: Validate that alarms sent to tedge/alarms topic \ gets mapped as alarms in Cumulocity
07:05:40 INFO  ==============================================================
07:05:40 INFO  EnvironmentC8y Setup
07:05:41 INFO  Executed systemctl&lt;serv_mapper1&gt;, exit status 3
07:05:55 INFO  Executed sudo&lt;tedge_connect_c8y&gt;, exit status 0, duration 13 secs
07:05:55 INFO  Executed sudo&lt;tedge_connect_c8y_test&gt;, exit status 0
07:05:56 INFO  Executed systemctl&lt;serv_mosq2&gt;, exit status 0
07:05:56 INFO  Executed systemctl&lt;serv_mapper3&gt;, exit status 0
07:05:57 INFO  Executed tedge, exit status 0
07:05:57 INFO  Executed tedge, exit status 0
07:05:58 INFO  Executed tedge, exit status 0
07:05:58 INFO  Executed tedge, exit status 0
07:05:58 INFO  Executed tedge, exit status 0
07:06:00 WARN  ConnectionError occurred while running test - ('Connection aborted.', ConnectionResetError(104, 'Connection reset by peer'))
Traceback (most recent call last):
  File &quot;/home/pi/env-pysys/lib/python3.7/site-packages/urllib3/connectionpool.py&quot;, line 710, in urlopen
    chunked=chunked,
  File &quot;/home/pi/env-pysys/lib/python3.7/site-packages/urllib3/connectionpool.py&quot;, line 386, in _make_request
    self._validate_conn(conn)
  File &quot;/home/pi/env-pysys/lib/python3.7/site-packages/urllib3/connectionpool.py&quot;, line 1040, in _validate_conn
    conn.connect()
  File &quot;/home/pi/env-pysys/lib/python3.7/site-packages/urllib3/connection.py&quot;, line 424, in connect
    tls_in_tls=tls_in_tls,
  File &quot;/home/pi/env-pysys/lib/python3.7/site-packages/urllib3/util/ssl_.py&quot;, line 450, in ssl_wrap_socket
    sock, context, tls_in_tls, server_hostname=server_hostname
  File &quot;/home/pi/env-pysys/lib/python3.7/site-packages/urllib3/util/ssl_.py&quot;, line 493, in _ssl_wrap_socket_impl
    return ssl_context.wrap_socket(sock, server_hostname=server_hostname)
  File &quot;/usr/lib/python3.7/ssl.py&quot;, line 412, in wrap_socket
    session=session
  File &quot;/usr/lib/python3.7/ssl.py&quot;, line 853, in _create
    self.do_handshake()
  File &quot;/usr/lib/python3.7/ssl.py&quot;, line 1117, in do_handshake
    self._sslobj.do_handshake()
ConnectionResetError: [Errno 104] Connection reset by peer

During handling of the above exception, another exception occurred:

Traceback (most recent call last):
  File &quot;/home/pi/env-pysys/lib/python3.7/site-packages/requests/adapters.py&quot;, line 449, in send
    timeout=timeout
  File &quot;/home/pi/env-pysys/lib/python3.7/site-packages/urllib3/connectionpool.py&quot;, line 786, in urlopen
    method, url, error=e, _pool=self, _stacktrace=sys.exc_info()[2]
  File &quot;/home/pi/env-pysys/lib/python3.7/site-packages/urllib3/util/retry.py&quot;, line 550, in increment
    raise six.reraise(type(error), error, _stacktrace)
  File &quot;/home/pi/env-pysys/lib/python3.7/site-packages/urllib3/packages/six.py&quot;, line 769, in reraise
    raise value.with_traceback(tb)
  File &quot;/home/pi/env-pysys/lib/python3.7/site-packages/urllib3/connectionpool.py&quot;, line 710, in urlopen
    chunked=chunked,
  File &quot;/home/pi/env-pysys/lib/python3.7/site-packages/urllib3/connectionpool.py&quot;, line 386, in _make_request
    self._validate_conn(conn)
  File &quot;/home/pi/env-pysys/lib/python3.7/site-packages/urllib3/connectionpool.py&quot;, line 1040, in _validate_conn
    conn.connect()
  File &quot;/home/pi/env-pysys/lib/python3.7/site-packages/urllib3/connection.py&quot;, line 424, in connect
    tls_in_tls=tls_in_tls,
  File &quot;/home/pi/env-pysys/lib/python3.7/site-packages/urllib3/util/ssl_.py&quot;, line 450, in ssl_wrap_socket
    sock, context, tls_in_tls, server_hostname=server_hostname
  File &quot;/home/pi/env-pysys/lib/python3.7/site-packages/urllib3/util/ssl_.py&quot;, line 493, in _ssl_wrap_socket_impl
    return ssl_context.wrap_socket(sock, server_hostname=server_hostname)
  File &quot;/usr/lib/python3.7/ssl.py&quot;, line 412, in wrap_socket
    session=session
  File &quot;/usr/lib/python3.7/ssl.py&quot;, line 853, in _create
    self.do_handshake()
  File &quot;/usr/lib/python3.7/ssl.py&quot;, line 1117, in do_handshake
    self._sslobj.do_handshake()
urllib3.exceptions.ProtocolError: ('Connection aborted.', ConnectionResetError(104, 'Connection reset by peer'))

During handling of the above exception, another exception occurred:

Traceback (most recent call last):
  File &quot;/home/pi/env-pysys/lib/python3.7/site-packages/pysys/baserunner.py&quot;, line 1296, in __call__
    self.testObj.validate()
  File &quot;/home/pi/actions-runner/_work/thin-edge.io/thin-edge.io/tests/PySys/tedge_mapper_c8y/tedge_mapper_c8y_alarms/run.py&quot;, line 92, in validate
    alarms = self.cumulocity.get_last_n_alarms_from_device(self.project.deviceid, 3)
  File &quot;/home/pi/actions-runner/_work/thin-edge.io/thin-edge.io/tests/PySys/environments/cumulocity.py&quot;, line 200, in get_last_n_alarms_from_device
    url=self.c8y_url + &quot;/alarm/alarms&quot;, params=params, auth=self.auth
  File &quot;/home/pi/env-pysys/lib/python3.7/site-packages/requests/api.py&quot;, line 76, in get
    return request('get', url, params=params, **kwargs)
  File &quot;/home/pi/env-pysys/lib/python3.7/site-packages/requests/api.py&quot;, line 61, in request
    return session.request(method=method, url=url, **kwargs)
  File &quot;/home/pi/env-pysys/lib/python3.7/site-packages/requests/sessions.py&quot;, line 542, in request
    resp = self.send(prep, **send_kwargs)
  File &quot;/home/pi/env-pysys/lib/python3.7/site-packages/requests/sessions.py&quot;, line 655, in send
    r = adapter.send(request, **kwargs)
  File &quot;/home/pi/env-pysys/lib/python3.7/site-packages/requests/adapters.py&quot;, line 498, in send
    raise ConnectionError(err, request=request)
requests.exceptions.ConnectionError: ('Connection aborted.', ConnectionResetError(104, 'Connection reset by peer'))
07:06:00 WARN  ConnectionError: ('Connection aborted.', ConnectionResetError(104, 'Connection reset by peer')) ... blocked 
07:06:00 INFO  
07:06:00 INFO  cleanup:
07:06:01 INFO  Executed tedge, exit status 0
07:06:01 INFO  Executed tedge, exit status 0
07:06:01 INFO  Executed tedge, exit status 0
07:06:06 INFO  Executed sudo&lt;tedge_disconnect_c8y&gt;, exit status 0
07:06:06 INFO  Executed systemctl&lt;serv_mapper5&gt;, exit status 3
07:06:06 INFO  
07:06:06 INFO  Test duration: 26.25 secs
07:06:06 INFO  Test final outcome:  BLOCKED
07:06:06 INFO  Test outcome reason: ConnectionError: ('Connection aborted.', ConnectionResetError(104, 'Connection reset by peer'))
07:06:06 INFO  
</system-out>
	</testcase>
</testsuite>
