2022-07-22 16:53:38,445 INFO  ==============================================================
2022-07-22 16:53:38,446 INFO  Id:    SoftwareManagement.sm_apt_install_remove_default
2022-07-22 16:53:38,447 INFO  Dir:   software_management_end_to_end/
2022-07-22 16:53:38,448 INFO  Title: Validate end to end behaviour for the default plugin for installation and removal of packages
2022-07-22 16:53:38,449 INFO  ==============================================================
2022-07-22 16:53:38,455 INFO  Using sw id database: {'asciijump': '5475369', 'robotfindskitten': '5474869', 'squirrel3': '5475279', 'rolldice': '5152439', 'moon-buggy': '5439204', 'apple': '5495053', 'banana': '5494888', 'cherry': '5495382', 'watermelon': '5494510', 'registry': '8018911', 'hello-world': '8021526', 'docker/getting-started': '8021973', 'alpine': '7991792'}
2022-07-22 16:53:38,456 INFO  EnvironmentC8y Setup
2022-07-22 16:53:39,019 INFO  Executed systemctl<serv_mapper1>, exit status 3
2022-07-22 16:53:39,124 INFO  Restarting mosquitto too frequently in the last 10 seconds. It was only up for 4 seconds
2022-07-22 16:53:39,127 INFO  Delaying execution by 7 seconds
2022-07-22 16:54:00,081 INFO  Executed sudo<tedge_connect_c8y>, exit status 0, duration 13 secs
2022-07-22 16:54:00,698 INFO  Executed sudo<tedge_connect_c8y_test>, exit status 0
2022-07-22 16:54:01,176 INFO  Executed systemctl<serv_mosq2>, exit status 0
2022-07-22 16:54:01,643 INFO  Executed systemctl<serv_mapper3>, exit status 0
2022-07-22 16:54:03,863 INFO  State of current operation: SUCCESSFUL
2022-07-22 16:54:04,109 INFO  Assert that (False == value) with value=False ... passed
2022-07-22 16:54:04,334 INFO  Response status: 201
2022-07-22 16:54:04,335 INFO  Response to action: {
    "delivery": {
        "log": [],
        "time": "2022-07-22T16:54:04.306Z",
        "status": "PENDING"
    },
    "creationTime": "2022-07-22T16:54:04.283Z",
    "deviceId": "21273852",
    "deviceName": "m32sd10b",
    "self": "https://t493319102.eu-latest.cumulocity.com/devicecontrol/operations/21301509",
    "id": "21301509",
    "status": "PENDING",
    "description": "Apply software changes, triggered from PySys: [{'name': 'rolldice', 'id': '5152439', 'version': ' ', 'url': '', 'action': 'install'}]",
    "c8y_SoftwareUpdate": [
        {
            "name": "rolldice",
            "action": "install",
            "id": "5152439",
            "version": " ",
            "url": ""
        }
    ]
}
2022-07-22 16:54:04,336 INFO  Started operation: {'delivery': {'log': [], 'time': '2022-07-22T16:54:04.306Z', 'status': 'PENDING'}, 'creationTime': '2022-07-22T16:54:04.283Z', 'deviceId': '21273852', 'deviceName': 'm32sd10b', 'self': 'https://t493319102.eu-latest.cumulocity.com/devicecontrol/operations/21301509', 'id': '21301509', 'status': 'PENDING', 'description': "Apply software changes, triggered from PySys: [{'name': 'rolldice', 'id': '5152439', 'version': ' ', 'url': '', 'action': 'install'}]", 'c8y_SoftwareUpdate': [{'name': 'rolldice', 'action': 'install', 'id': '5152439', 'version': ' ', 'url': ''}]}
2022-07-22 16:54:06,557 INFO  State of operation 21301509 : PENDING
2022-07-22 16:54:08,791 INFO  State of operation 21301509 : EXECUTING
2022-07-22 16:54:11,009 INFO  State of operation 21301509 : EXECUTING
2022-07-22 16:54:13,230 INFO  State of operation 21301509 : EXECUTING
2022-07-22 16:54:15,472 INFO  State of operation 21301509 : EXECUTING
2022-07-22 16:54:17,688 INFO  State of operation 21301509 : EXECUTING
2022-07-22 16:54:20,629 INFO  State of operation 21301509 : EXECUTING
2022-07-22 16:54:23,510 INFO  State of operation 21301509 : EXECUTING
2022-07-22 16:54:26,140 INFO  State of operation 21301509 : EXECUTING
2022-07-22 16:54:28,408 INFO  State of operation 21301509 : EXECUTING
2022-07-22 16:54:30,642 INFO  State of operation 21301509 : EXECUTING
2022-07-22 16:54:32,864 INFO  State of operation 21301509 : EXECUTING
2022-07-22 16:54:35,091 INFO  State of operation 21301509 : EXECUTING
2022-07-22 16:54:37,320 INFO  State of operation 21301509 : EXECUTING
2022-07-22 16:54:39,649 INFO  State of operation 21301509 : EXECUTING
2022-07-22 16:54:42,391 INFO  State of operation 21301509 : EXECUTING
2022-07-22 16:54:44,612 INFO  State of operation 21301509 : EXECUTING
2022-07-22 16:54:46,840 INFO  State of operation 21301509 : EXECUTING
2022-07-22 16:54:49,060 INFO  State of operation 21301509 : EXECUTING
2022-07-22 16:54:51,885 INFO  State of operation 21301509 : EXECUTING
2022-07-22 16:54:54,093 INFO  State of operation 21301509 : EXECUTING
2022-07-22 16:54:56,783 INFO  State of operation 21301509 : EXECUTING
2022-07-22 16:54:59,001 INFO  State of operation 21301509 : EXECUTING
2022-07-22 16:55:01,739 INFO  State of operation 21301509 : EXECUTING
2022-07-22 16:55:03,962 INFO  State of operation 21301509 : EXECUTING
2022-07-22 16:55:06,728 INFO  State of operation 21301509 : EXECUTING
2022-07-22 16:55:08,950 INFO  State of operation 21301509 : EXECUTING
2022-07-22 16:55:11,262 INFO  State of operation 21301509 : EXECUTING
2022-07-22 16:55:13,487 INFO  State of operation 21301509 : EXECUTING
2022-07-22 16:55:15,703 INFO  State of operation 21301509 : EXECUTING
2022-07-22 16:55:17,924 INFO  State of operation 21301509 : EXECUTING
2022-07-22 16:55:20,133 INFO  State of operation 21301509 : SUCCESSFUL
2022-07-22 16:55:20,351 INFO  Package rolldice is installed
2022-07-22 16:55:20,353 INFO  Assert that (True == value) with value=True ... passed
2022-07-22 16:55:20,585 INFO  Response status: 201
2022-07-22 16:55:20,586 INFO  Response to action: {
    "delivery": {
        "log": [],
        "time": "2022-07-22T16:55:20.557Z",
        "status": "PENDING"
    },
    "creationTime": "2022-07-22T16:55:20.534Z",
    "deviceId": "21273852",
    "deviceName": "m32sd10b",
    "self": "https://t493319102.eu-latest.cumulocity.com/devicecontrol/operations/21301525",
    "id": "21301525",
    "status": "PENDING",
    "description": "Apply software changes, triggered from PySys: [{'name': 'rolldice', 'id': '5152439', 'version': ' ', 'url': '', 'action': 'delete'}]",
    "c8y_SoftwareUpdate": [
        {
            "name": "rolldice",
            "action": "delete",
            "id": "5152439",
            "version": " ",
            "url": ""
        }
    ]
}
2022-07-22 16:55:20,587 INFO  Started operation: {'delivery': {'log': [], 'time': '2022-07-22T16:55:20.557Z', 'status': 'PENDING'}, 'creationTime': '2022-07-22T16:55:20.534Z', 'deviceId': '21273852', 'deviceName': 'm32sd10b', 'self': 'https://t493319102.eu-latest.cumulocity.com/devicecontrol/operations/21301525', 'id': '21301525', 'status': 'PENDING', 'description': "Apply software changes, triggered from PySys: [{'name': 'rolldice', 'id': '5152439', 'version': ' ', 'url': '', 'action': 'delete'}]", 'c8y_SoftwareUpdate': [{'name': 'rolldice', 'action': 'delete', 'id': '5152439', 'version': ' ', 'url': ''}]}
2022-07-22 16:55:22,791 INFO  State of operation 21301525 : PENDING
2022-07-22 16:55:25,026 INFO  State of operation 21301525 : EXECUTING
2022-07-22 16:55:27,243 INFO  State of operation 21301525 : EXECUTING
2022-07-22 16:55:29,452 INFO  State of operation 21301525 : EXECUTING
2022-07-22 16:55:31,664 INFO  State of operation 21301525 : EXECUTING
2022-07-22 16:55:33,884 INFO  State of operation 21301525 : EXECUTING
2022-07-22 16:55:36,580 INFO  State of operation 21301525 : EXECUTING
2022-07-22 16:55:39,325 INFO  State of operation 21301525 : EXECUTING
2022-07-22 16:55:41,563 INFO  State of operation 21301525 : EXECUTING
2022-07-22 16:55:44,272 WARN  ConnectionError occurred while running test - ('Connection aborted.', ConnectionResetError(104, 'Connection reset by peer'))
Traceback (most recent call last):
  File "/home/pi/env-pysys/lib/python3.7/site-packages/urllib3/connectionpool.py", line 710, in urlopen
    chunked=chunked,
  File "/home/pi/env-pysys/lib/python3.7/site-packages/urllib3/connectionpool.py", line 386, in _make_request
    self._validate_conn(conn)
  File "/home/pi/env-pysys/lib/python3.7/site-packages/urllib3/connectionpool.py", line 1040, in _validate_conn
    conn.connect()
  File "/home/pi/env-pysys/lib/python3.7/site-packages/urllib3/connection.py", line 424, in connect
    tls_in_tls=tls_in_tls,
  File "/home/pi/env-pysys/lib/python3.7/site-packages/urllib3/util/ssl_.py", line 450, in ssl_wrap_socket
    sock, context, tls_in_tls, server_hostname=server_hostname
  File "/home/pi/env-pysys/lib/python3.7/site-packages/urllib3/util/ssl_.py", line 493, in _ssl_wrap_socket_impl
    return ssl_context.wrap_socket(sock, server_hostname=server_hostname)
  File "/usr/lib/python3.7/ssl.py", line 412, in wrap_socket
    session=session
  File "/usr/lib/python3.7/ssl.py", line 853, in _create
    self.do_handshake()
  File "/usr/lib/python3.7/ssl.py", line 1117, in do_handshake
    self._sslobj.do_handshake()
ConnectionResetError: [Errno 104] Connection reset by peer

During handling of the above exception, another exception occurred:

Traceback (most recent call last):
  File "/home/pi/env-pysys/lib/python3.7/site-packages/requests/adapters.py", line 449, in send
    timeout=timeout
  File "/home/pi/env-pysys/lib/python3.7/site-packages/urllib3/connectionpool.py", line 786, in urlopen
    method, url, error=e, _pool=self, _stacktrace=sys.exc_info()[2]
  File "/home/pi/env-pysys/lib/python3.7/site-packages/urllib3/util/retry.py", line 550, in increment
    raise six.reraise(type(error), error, _stacktrace)
  File "/home/pi/env-pysys/lib/python3.7/site-packages/urllib3/packages/six.py", line 769, in reraise
    raise value.with_traceback(tb)
  File "/home/pi/env-pysys/lib/python3.7/site-packages/urllib3/connectionpool.py", line 710, in urlopen
    chunked=chunked,
  File "/home/pi/env-pysys/lib/python3.7/site-packages/urllib3/connectionpool.py", line 386, in _make_request
    self._validate_conn(conn)
  File "/home/pi/env-pysys/lib/python3.7/site-packages/urllib3/connectionpool.py", line 1040, in _validate_conn
    conn.connect()
  File "/home/pi/env-pysys/lib/python3.7/site-packages/urllib3/connection.py", line 424, in connect
    tls_in_tls=tls_in_tls,
  File "/home/pi/env-pysys/lib/python3.7/site-packages/urllib3/util/ssl_.py", line 450, in ssl_wrap_socket
    sock, context, tls_in_tls, server_hostname=server_hostname
  File "/home/pi/env-pysys/lib/python3.7/site-packages/urllib3/util/ssl_.py", line 493, in _ssl_wrap_socket_impl
    return ssl_context.wrap_socket(sock, server_hostname=server_hostname)
  File "/usr/lib/python3.7/ssl.py", line 412, in wrap_socket
    session=session
  File "/usr/lib/python3.7/ssl.py", line 853, in _create
    self.do_handshake()
  File "/usr/lib/python3.7/ssl.py", line 1117, in do_handshake
    self._sslobj.do_handshake()
urllib3.exceptions.ProtocolError: ('Connection aborted.', ConnectionResetError(104, 'Connection reset by peer'))

During handling of the above exception, another exception occurred:

Traceback (most recent call last):
  File "/home/pi/env-pysys/lib/python3.7/site-packages/pysys/baserunner.py", line 1294, in __call__
    self.testObj.execute()
  File "/home/pi/actions-runner/_work/thin-edge.io/thin-edge.io/tests/PySys/software_management_end_to_end/sm_apt_install_remove_default/run.py", line 39, in execute
    self.wait_until_succcess()
  File "/home/pi/actions-runner/_work/thin-edge.io/thin-edge.io/tests/PySys/software_management_end_to_end/environment_sm_management.py", line 324, in wait_until_succcess
    self.wait_until_status("SUCCESSFUL")
  File "/home/pi/actions-runner/_work/thin-edge.io/thin-edge.io/tests/PySys/software_management_end_to_end/environment_sm_management.py", line 354, in wait_until_status
    current_status = self.get_status_of_operation()
  File "/home/pi/actions-runner/_work/thin-edge.io/thin-edge.io/tests/PySys/software_management_end_to_end/environment_sm_management.py", line 300, in get_status_of_operation
    req = requests.get(url, headers=self.header, timeout=self.timeout_req)
  File "/home/pi/env-pysys/lib/python3.7/site-packages/requests/api.py", line 76, in get
    return request('get', url, params=params, **kwargs)
  File "/home/pi/env-pysys/lib/python3.7/site-packages/requests/api.py", line 61, in request
    return session.request(method=method, url=url, **kwargs)
  File "/home/pi/env-pysys/lib/python3.7/site-packages/requests/sessions.py", line 542, in request
    resp = self.send(prep, **send_kwargs)
  File "/home/pi/env-pysys/lib/python3.7/site-packages/requests/sessions.py", line 655, in send
    r = adapter.send(request, **kwargs)
  File "/home/pi/env-pysys/lib/python3.7/site-packages/requests/adapters.py", line 498, in send
    raise ConnectionError(err, request=request)
requests.exceptions.ConnectionError: ('Connection aborted.', ConnectionResetError(104, 'Connection reset by peer'))
2022-07-22 16:55:44,764 WARN  ConnectionError: ('Connection aborted.', ConnectionResetError(104, 'Connection reset by peer')) ... blocked 
2022-07-22 16:55:44,766 INFO  
2022-07-22 16:55:44,766 INFO  cleanup:
2022-07-22 16:55:49,029 INFO  Executed sudo<tedge_disconnect_c8y>, exit status 0
2022-07-22 16:55:49,592 INFO  Executed systemctl<serv_mapper5>, exit status 3
2022-07-22 16:55:49,596 INFO  
2022-07-22 16:55:49,597 INFO  Test duration: 131.16 secs
2022-07-22 16:55:49,598 INFO  Test final outcome:  BLOCKED
2022-07-22 16:55:49,599 INFO  Test outcome reason: ConnectionError: ('Connection aborted.', ConnectionResetError(104, 'Connection reset by peer'))
2022-07-22 16:55:49,600 INFO  
