2022-05-24 10:39:56,396 INFO  ==============================================================
2022-05-24 10:39:56,397 INFO  Id:    log_request_error_messages
2022-05-24 10:39:56,398 INFO  Dir:   log_request_end_to_end/
2022-05-24 10:39:56,399 INFO  Title: Validate end to end behaviour for the log request operation check for error messages
2022-05-24 10:39:56,399 INFO  ==============================================================
2022-05-24 10:39:57,680 INFO  EnvironmentC8y Setup
2022-05-24 10:39:58,243 INFO  Executed systemctl<serv_mapper1>, exit status 3
2022-05-24 10:39:58,353 INFO  Restarting mosquitto too frequently in the last 10 seconds. It was only up for 2 seconds
2022-05-24 10:39:58,354 INFO  Delaying execution by 9 seconds
2022-05-24 10:40:21,302 INFO  Executed sudo<tedge_connect_c8y>, exit status 0, duration 13 secs
2022-05-24 10:40:21,972 INFO  Executed sudo<tedge_connect_c8y_test>, exit status 0
2022-05-24 10:40:22,485 INFO  Executed systemctl<serv_mosq2>, exit status 0
2022-05-24 10:40:22,953 INFO  Executed systemctl<serv_mapper3>, exit status 0
2022-05-24 10:40:23,467 INFO  Executed sudo<rm_logs>, exit status 0
2022-05-24 10:40:24,000 INFO  Executed sudo<move_logs>, exit status 0
2022-05-24 10:40:24,489 INFO  log response None
2022-05-24 10:40:24,500 WARN  retry, retrying in 1 seconds...
2022-05-24 10:40:25,709 INFO  log response None
2022-05-24 10:40:25,710 WARN  retry, retrying in 1 seconds...
2022-05-24 10:40:26,913 INFO  log response None
2022-05-24 10:40:26,914 WARN  retry, retrying in 1 seconds...
2022-05-24 10:40:28,274 INFO  log response None
2022-05-24 10:40:28,275 WARN  retry, retrying in 1 seconds...
2022-05-24 10:40:29,479 INFO  log response None
2022-05-24 10:40:29,480 WARN  retry, retrying in 1 seconds...
2022-05-24 10:40:30,698 INFO  log response None
2022-05-24 10:40:30,699 WARN  retry, retrying in 1 seconds...
2022-05-24 10:40:32,043 INFO  log response None
2022-05-24 10:40:32,045 WARN  retry, retrying in 1 seconds...
2022-05-24 10:40:33,316 INFO  log response None
2022-05-24 10:40:33,317 WARN  retry, retrying in 1 seconds...
2022-05-24 10:40:34,528 INFO  log response None
2022-05-24 10:40:34,529 WARN  retry, retrying in 1 seconds...
2022-05-24 10:40:35,737 INFO  log response None
2022-05-24 10:40:35,738 WARN  retry, retrying in 1 seconds...
2022-05-24 10:40:36,946 INFO  log response None
2022-05-24 10:40:36,947 WARN  retry, retrying in 1 seconds...
2022-05-24 10:40:38,157 INFO  log response None
2022-05-24 10:40:38,158 WARN  retry, retrying in 1 seconds...
2022-05-24 10:40:39,370 INFO  log response None
2022-05-24 10:40:39,372 WARN  retry, retrying in 1 seconds...
2022-05-24 10:40:40,580 INFO  log response None
2022-05-24 10:40:40,582 WARN  retry, retrying in 1 seconds...
2022-05-24 10:40:42,043 INFO  log response None
2022-05-24 10:40:42,044 WARN  retry, retrying in 1 seconds...
2022-05-24 10:40:43,248 INFO  log response None
2022-05-24 10:40:43,249 WARN  retry, retrying in 1 seconds...
2022-05-24 10:40:44,458 INFO  log response None
2022-05-24 10:40:44,459 WARN  retry, retrying in 1 seconds...
2022-05-24 10:40:45,670 INFO  log response None
2022-05-24 10:40:45,671 WARN  retry, retrying in 1 seconds...
2022-05-24 10:40:46,873 INFO  log response None
2022-05-24 10:40:46,875 WARN  retry, retrying in 1 seconds...
2022-05-24 10:40:48,077 INFO  log response None
2022-05-24 10:40:48,078 WARN  Exception occurred while running test - retry
Traceback (most recent call last):
  File "/home/pi/env-pysys/lib/python3.7/site-packages/pysys/baserunner.py", line 1296, in __call__
    self.testObj.validate()
  File "/home/pi/actions-runner/_work/thin-edge.io/thin-edge.io/tests/PySys/log_request_end_to_end/log_request_error_messages/run.py", line 43, in validate
    self.assertThat("True == value", value=self.wait_until_logs_retrieved())
  File "/home/pi/env-pysys/lib/python3.7/site-packages/decorator.py", line 232, in fun
    return caller(func, *(extras + args), **kw)
  File "/home/pi/env-pysys/lib/python3.7/site-packages/retry/api.py", line 74, in retry_decorator
    logger)
  File "/home/pi/env-pysys/lib/python3.7/site-packages/retry/api.py", line 33, in __retry_internal
    return f()
  File "/home/pi/actions-runner/_work/thin-edge.io/thin-edge.io/tests/PySys/log_request_end_to_end/log_request_error_messages/run.py", line 52, in wait_until_logs_retrieved
    raise Exception("retry")
Exception: retry
2022-05-24 10:40:48,134 WARN  Exception: retry ... blocked 
2022-05-24 10:40:48,135 INFO  
2022-05-24 10:40:48,136 INFO  cleanup:
2022-05-24 10:40:48,651 INFO  Executed sudo<rm_logs>, exit status 0
2022-05-24 10:40:49,170 INFO  Executed sudo<rm_tmp_logs>, exit status 0
2022-05-24 10:40:49,682 INFO  Executed sudo<send_failed>, exit status 0
2022-05-24 10:40:54,080 INFO  Executed sudo<tedge_disconnect_c8y>, exit status 0
2022-05-24 10:40:54,664 INFO  Executed systemctl<serv_mapper5>, exit status 3
2022-05-24 10:40:54,668 INFO  
2022-05-24 10:40:54,669 INFO  Test duration: 58.28 secs
2022-05-24 10:40:54,670 INFO  Test final outcome:  BLOCKED
2022-05-24 10:40:54,671 INFO  Test outcome reason: Exception: retry
2022-05-24 10:40:54,672 INFO  
