2022-06-02 08:31:35,086 INFO  ==============================================================
2022-06-02 08:31:35,087 INFO  Id:    log_request_error_messages
2022-06-02 08:31:35,089 INFO  Dir:   log_request_end_to_end/
2022-06-02 08:31:35,089 INFO  Title: Validate end to end behaviour for the log request operation check for error messages
2022-06-02 08:31:35,090 INFO  ==============================================================
2022-06-02 08:31:36,485 INFO  EnvironmentC8y Setup
2022-06-02 08:31:37,301 INFO  Executed systemctl<serv_mapper1>, exit status 3
2022-06-02 08:31:51,388 INFO  Executed sudo<tedge_connect_c8y>, exit status 0, duration 13 secs
2022-06-02 08:31:52,011 INFO  Executed sudo<tedge_connect_c8y_test>, exit status 0
2022-06-02 08:31:52,677 INFO  Executed systemctl<serv_mosq2>, exit status 0
2022-06-02 08:31:53,141 INFO  Executed systemctl<serv_mapper3>, exit status 0
2022-06-02 08:31:53,654 INFO  Executed sudo<rm_logs>, exit status 0
2022-06-02 08:31:54,191 INFO  Executed sudo<move_logs>, exit status 0
2022-06-02 08:31:54,702 INFO  log response None
2022-06-02 08:31:54,704 WARN  retry, retrying in 1 seconds...
2022-06-02 08:31:55,921 INFO  log response None
2022-06-02 08:31:55,922 WARN  retry, retrying in 1 seconds...
2022-06-02 08:31:57,128 INFO  log response None
2022-06-02 08:31:57,129 WARN  retry, retrying in 1 seconds...
2022-06-02 08:31:58,348 INFO  log response None
2022-06-02 08:31:58,349 WARN  retry, retrying in 1 seconds...
2022-06-02 08:31:59,576 INFO  log response None
2022-06-02 08:31:59,577 WARN  retry, retrying in 1 seconds...
2022-06-02 08:32:00,789 INFO  log response None
2022-06-02 08:32:00,792 WARN  retry, retrying in 1 seconds...
2022-06-02 08:32:02,006 INFO  log response None
2022-06-02 08:32:02,008 WARN  retry, retrying in 1 seconds...
2022-06-02 08:32:03,223 INFO  log response None
2022-06-02 08:32:03,224 WARN  retry, retrying in 1 seconds...
2022-06-02 08:32:04,438 INFO  log response None
2022-06-02 08:32:04,439 WARN  retry, retrying in 1 seconds...
2022-06-02 08:32:05,656 INFO  log response None
2022-06-02 08:32:05,657 WARN  retry, retrying in 1 seconds...
2022-06-02 08:32:06,881 INFO  log response None
2022-06-02 08:32:06,882 WARN  retry, retrying in 1 seconds...
2022-06-02 08:32:08,094 INFO  log response None
2022-06-02 08:32:08,095 WARN  retry, retrying in 1 seconds...
2022-06-02 08:32:09,340 INFO  log response None
2022-06-02 08:32:09,341 WARN  retry, retrying in 1 seconds...
2022-06-02 08:32:10,558 INFO  log response None
2022-06-02 08:32:10,559 WARN  retry, retrying in 1 seconds...
2022-06-02 08:32:11,782 INFO  log response None
2022-06-02 08:32:11,784 WARN  retry, retrying in 1 seconds...
2022-06-02 08:32:12,996 INFO  log response None
2022-06-02 08:32:12,997 WARN  retry, retrying in 1 seconds...
2022-06-02 08:32:14,221 INFO  log response None
2022-06-02 08:32:14,222 WARN  retry, retrying in 1 seconds...
2022-06-02 08:32:15,427 INFO  log response None
2022-06-02 08:32:15,428 WARN  retry, retrying in 1 seconds...
2022-06-02 08:32:16,633 INFO  log response None
2022-06-02 08:32:16,634 WARN  retry, retrying in 1 seconds...
2022-06-02 08:32:17,849 INFO  log response None
2022-06-02 08:32:17,851 WARN  Exception occurred while running test - retry
Traceback (most recent call last):
  File "/home/pi/env-pysys/lib/python3.7/site-packages/pysys/baserunner.py", line 1296, in __call__
    self.testObj.validate()
  File "/home/pi/actions-runner/_work/thin-edge.io/thin-edge.io/tests/PySys/log_request_end_to_end/log_request_error_messages/run.py", line 43, in validate
    self.assertThat("True == value", value=self.wait_until_logs_retrieved())
  File "/home/pi/env-pysys/lib/python3.7/site-packages/decorator.py", line 232, in fun
    return caller(func, *(extras + args), **kw)
  File "/home/pi/env-pysys/lib/python3.7/site-packages/retry/api.py", line 74, in retry_decorator
    logger)
  File "/home/pi/env-pysys/lib/python3.7/site-packages/retry/api.py", line 33, in __retry_internal
    return f()
  File "/home/pi/actions-runner/_work/thin-edge.io/thin-edge.io/tests/PySys/log_request_end_to_end/log_request_error_messages/run.py", line 52, in wait_until_logs_retrieved
    raise Exception("retry")
Exception: retry
2022-06-02 08:32:17,969 WARN  Exception: retry ... blocked 
2022-06-02 08:32:17,970 INFO  
2022-06-02 08:32:17,971 INFO  cleanup:
2022-06-02 08:32:18,483 INFO  Executed sudo<rm_logs>, exit status 0
2022-06-02 08:32:19,047 INFO  Executed sudo<rm_tmp_logs>, exit status 0
2022-06-02 08:32:19,765 INFO  Executed sudo<send_failed>, exit status 0
2022-06-02 08:32:23,695 INFO  Executed sudo<tedge_disconnect_c8y>, exit status 0
2022-06-02 08:32:24,259 INFO  Executed systemctl<serv_mapper5>, exit status 3
2022-06-02 08:32:24,263 INFO  
2022-06-02 08:32:24,264 INFO  Test duration: 49.18 secs
2022-06-02 08:32:24,265 INFO  Test final outcome:  BLOCKED
2022-06-02 08:32:24,266 INFO  Test outcome reason: Exception: retry
2022-06-02 08:32:24,267 INFO  
